MarketOrder/input.txt
16
N,1,0000001,ALN,L,B,60.90,100
N,2,0000002,ALN,L,B,60.99,100
N,3,0000002,ALN,L,B,61.99,100
N,4,0000003,ALN,L,B,61.99,100
N,10,0000003,ALN,L,S,60.90,100
N,12,0000004,ALN,L,S,60.90,100
N,11,0000005,ALB,L,S,60.90,100
N,14,0000006,ALB,L,S,62.90,101
N,16,0000007,ALB,L,S,63.90,102
N,18,0000008,ALB,L,S,64.90,103
N,20,0000009,ALB,L,S,65.90,104
V,0000003
V,ALB
V,ALN,0000002
V,0000002,ALN
Q
